Workbook

Sheet 表紙
E4: 総務省様 御中
A17: Webフォーム_調査書類発送受付フォーム画面設計書
A29: 46079
A32: 第1.0.0版

Sheet 変更履歴
A1: システム名 | J1: 令和8年度経済センサス活動調査 | AA1: 変更履歴 | AP1: 文書番号
A2: サブシステム名 | J2: - | AP2: 更新日 | AU2: 46079 | BA2: 更新者 | BF2: 方
A4: 項番 | B4: 版数 | F4: 変更箇所 | N4: 内容 | AT4: 変更日 | AY4: 変更者 | BC4: 承認日 | BH4: 承認者
A6: 1 | B6: 1.0.0 | F6: 全て | N6: 新規作成 | AT6: 46079 | AY6: 方

Sheet 画面定義書Step1
A1: システム名 | G1: 令和8年度経済センサス活動調査 | S1: 画 面 定 義 書 | BC1: 文書番号
A2: サブシステム名 | G2: - | BC2: 更新日 | BG2: 46078 | BL2: 更新者 | BP2: 方
A4: 機能ID | I4: 画面ID | U4: 画面名 | AA4: 調査書類発送受付フォーム画面_Step1 | AQ4: documentsResendFormInput | BG4: 分類 | BL4: カスタム画面
A5: 画面イメージ | BC5: 操作説明
B6: ■調査書類発送受付フォーム入力画面 | BC6: ■調査書類発送受付フォーム入力画面 入力画面の一覧となります。すべての必須項目を入力した上で、「入力内容の確認」ボタンをクリックし、入力に問題がない場合、Step2の「入力内容確認」画面へ遷移します。
B81: ■未入力、「入力内容の確認」ボタンをクリックした場合 | BC81: ■未入力、「入力内容の確認」ボタンをクリックした場合 必須項目が未入力の状態で「入力内容の確認」ボタンをクリックすると、画面キャプチャーのようにエラーメッセージが表示されます。
B173: ■事業所の郵便番号 | BC173: ■事業所の郵便番号 6桁の番号以外を入力する場合、エラーチェックが発生する。
B185: ■申請者の電話番号 | BC185: ■申請者の電話番号 半角数字と + - ( )以外を入力した場合、チェックエラーが発生する。
B197: ■申請者のメールアドレス | BC197: ■申請者のメールアドレス ■メールアドレス、メールアドレスの確認 ①メールアドレス確認がメールアドレスと一致しない場合、チェックエラーが発生する。 ②入力した「メールアドレス」のメールアドレスのフォマードをチェックします、メールアドレスの形式が正しくない場合「ご担当者のメールアドレスを正しいフォーマットで入力してください」というエラーメッセージが表示されます。 正規表現を使用してメールアドレスの形式をチェックします： • ^ - 文字列の開始 • [A-Za-z0-9]{1} - 最初の文字は英数字のみ • [A-Za-z0-9_.\-+]* - その後は英数字、アンダースコア、ドット、ハイフン、プラス記号が可能 • @{1} - @マークが必須 • [A-Za-z0-9_.-]+ - @の後には英数字、アンダースコア、ドット、ハイフンが1文字以上必要 • \. - ドットが必須 • [A-Za-z0-9]+ - ドメイン部分は英数字が1文字以上必要 • $ - 文字列の終わり 例えば： valid@example.com （有効） user.name+tag@domain.com （有効） @invalid.com （@マークの前に文字がないため無効） invalid@ （ドットがないため無効）
BC209: ■書類のお届け先の郵便番号 6桁の番号以外を入力する場合、エラーチェックが発生する。
B210: ■書類のお届け先の郵便番号

Sheet 画面定義書Step2
A1: システム名 | G1: 令和8年度経済センサス活動調査 | S1: 画 面 定 義 書 | BC1: 文書番号
A2: サブシステム名 | G2: - | BC2: 更新日 | BG2: 46078 | BL2: 更新者 | BP2: 方
A4: 機能ID | I4: 画面ID | U4: 画面名 | AA4: 調査書類発送受付フォーム画面_Step2 | AQ4: documentsResendFormConfirm | BG4: 分類 | BL4: カスタム画面
A5: 画面イメージ | BC5: 操作説明
B6: ■修繕申し込みフォーム入力内容確認画面 | BC6: ■調査書類発送受付フォーム入力内容確認画面 Step1の調査書類発送受付フォーム画面で、入力した内容が表示される Step1の調査書類発送受付フォーム画面で、「入力内容の確認」ボタンをクリックし、入力に問題がない場合、こちらの「入力内容確認」画面に遷移します 「送信する」ボタン押下後、完了画面に遷移します。そして、問合せ内容がSalesforce（ケース）に登録されます。 ※お客様にお問い合わせ メールを通知します 「入力画面へもどり修正する」ボタン押下後、入力画面に遷移します ※「入力内容確認」の画面には、お客様がStep1の調査書類発送受付フォームで入力した内容のみが表示されます

Sheet 画面定義書Step3
A1: システム名 | G1: 令和8年度経済センサス活動調査 | S1: 画 面 定 義 書 | BC1: 文書番号
A2: サブシステム名 | G2: - | BC2: 更新日 | BG2: 46078 | BL2: 更新者 | BP2: 方
A4: 機能ID | I4: 画面ID | U4: 画面名 | AA4: 調査書類発送受付フォーム画面_Step3 | AQ4: documentsResendFormSuccess | BG4: 分類 | BL4: カスタム画面
A5: 画面イメージ | BC5: 操作説明
B6: ■調査書類発送受付フォーム提出完了画面 | BC6: ■調査書類発送受付フォーム提出完了画面 「トップページにもどる」ボタンを押した場合、「https://e-census2026--dev.sandbox.my.site.com/s/」に遷移される。
BC20: ■お知らせ本文 Salesforceのカスタムメタデータ型「問い合わせフォーム関連設定」で管理しています。動的に変更は可能です。

Sheet 画面項目定義書
A1: システム名 | G1: 令和8年度経済センサス活動調査 | S1: 画 面 項 目 定 義 書 | AT1: 文書番号 | AX1: =IF(ISBLANK(画面定義書Step1!BG1),"",画面定義書Step1!BG1)
A2: サブシステム名 | G2: =IF(ISBLANK(画面定義書Step1!G2),"",画面定義書Step1!G2) -> - | AT2: 更新日 | AX2: 46079 | BC2: 更新者 | BG2: 方
A4: 機能ID | E4: =IF(ISBLANK(画面定義書Step1!E4),"",画面定義書Step1!E4) | I4: 画面ID | O4: =IF(ISBLANK(画面定義書Step1!O4),"",画面定義書Step1!O4) | U4: 画面名 | AA4: 調査書類発送受付フォーム画面 | AM4: documentsResendFormPa | AX4: 分類 | BC4: =IF(ISBLANK(画面定義書Step1!BL4),"",画面定義書Step1!BL4) -> カスタム画面
A5: 項番 | B5: 入出力 | AH5: チェック仕様 | BC5: 備考
AG6: 必須 | AH6: 文字数 | AL6: 数値 | AP6: 半角 | AU6: 全角 | AV6: 日付 | AW6: フォーマット
B7: 論理名 | K7: 物理名 | T7: I/O | V7: 入出力タイプ | AB7: 初期値 | AH7: 最小 | AJ7: 最大 | AL7: 最小 | AN7: 最大 | AP7: 全 | AQ7: 英 | AR7: 数 | AS7: ｶ | AT7: 記
B8: ■解約申し込みフォーム個人
A9: =ROW()-8 -> 1 | B9: 事業所の名称 | K9: companyName | T9: I | V9: テキスト | BC9: 使用項目：ケース(Case) .事業所の名称 (BusinessPersonName__c)
A10: =ROW()-8 -> 2 | B10: 事業所の郵便番号 | K10: companyPostcode | L10: ResidentName__c | M10: ResidentName__c | N10: ResidentName__c | O10: ResidentName__c | P10: ResidentName__c | Q10: ResidentName__c | R10: ResidentName__c | S10: ResidentName__c | T10: I | V10: テキスト | BC10: 使用項目：ケース(Case) .事業所の郵便番号 (BusinessPersonPostCode__c)
A11: =ROW()-8 -> 3 | B11: 事業所の住所 | K11: companyAddress | L11: SuppliedPhone__c | M11: SuppliedPhone__c | N11: SuppliedPhone__c | O11: SuppliedPhone__c | P11: SuppliedPhone__c | Q11: SuppliedPhone__c | R11: SuppliedPhone__c | S11: SuppliedPhone__c | T11: I | V11: テキスト | BC11: 使用項目：ケース(Case) .事業所の住所 (BusinessPersonAddress__c)
A12: =ROW()-8 -> 4 | B12: 法人番号 | K12: corporationNumber | L12: SuppliedEmail | M12: SuppliedEmail | N12: SuppliedEmail | O12: SuppliedEmail | P12: SuppliedEmail | Q12: SuppliedEmail | R12: SuppliedEmail | S12: SuppliedEmail | T12: I | V12: テキスト | BC12: 使用項目：ケース(Case) .事業所の法人番号 (CorporationNumber__c)
A13: =ROW()-8 -> 5 | B13: 申請者の氏名 | K13: applicantName | L13: SuppliedEmailConfirm__c | M13: SuppliedEmailConfirm__c | N13: SuppliedEmailConfirm__c | O13: SuppliedEmailConfirm__c | P13: SuppliedEmailConfirm__c | Q13: SuppliedEmailConfirm__c | R13: SuppliedEmailConfirm__c | S13: SuppliedEmailConfirm__c | T13: I | V13: テキスト | BC13: 使用項目：ケース(Case) .ご連絡いただいた方の氏名 (ChargeName__c)
A14: =ROW()-8 -> 6 | B14: 申請者の部署名 | K14: applicantDepartment | L14: ContractPostalCode__c | M14: ContractPostalCode__c | N14: ContractPostalCode__c | O14: ContractPostalCode__c | P14: ContractPostalCode__c | Q14: ContractPostalCode__c | R14: ContractPostalCode__c | S14: ContractPostalCode__c | T14: I | V14: テキスト | BC14: 使用項目：ケース(Case) .ご連絡いただいた方の部署 (ChargeDepartment__c)
A15: =ROW()-8 -> 7 | B15: 申請者の電話番号 | K15: applicantPhone | L15: ContractPrefecture__c | M15: ContractPrefecture__c | N15: ContractPrefecture__c | O15: ContractPrefecture__c | P15: ContractPrefecture__c | Q15: ContractPrefecture__c | R15: ContractPrefecture__c | S15: ContractPrefecture__c | T15: I | V15: テキスト | W15: 単数選択リスト | X15: 単数選択リスト | Y15: 単数選択リスト | Z15: 単数選択リスト | AA15: 単数選択リスト | BC15: 使用項目：ケース(Case) .ご連絡いただいた方の電話番号 (ChargePhoneNumber__c)
A16: =ROW()-8 -> 8 | B16: 申請者のメールアドレス | K16: applicantMail | L16: ContractCity__c | M16: ContractCity__c | N16: ContractCity__c | O16: ContractCity__c | P16: ContractCity__c | Q16: ContractCity__c | R16: ContractCity__c | S16: ContractCity__c | T16: I | V16: テキスト | W16: テキスト | X16: テキスト | Y16: テキスト | Z16: テキスト | AA16: テキスト | BC16: 使用項目：ケース(Case) .ご連絡いただいた方のメール (ChargeEmail__c)
A17: =ROW()-8 -> 9 | B17: 市区町村コード | K17: surveyId | L17: ContractStreetAddress__c | M17: ContractStreetAddress__c | N17: ContractStreetAddress__c | O17: ContractStreetAddress__c | P17: ContractStreetAddress__c | Q17: ContractStreetAddress__c | R17: ContractStreetAddress__c | S17: ContractStreetAddress__c | T17: I | V17: テキスト | W17: 電話 | X17: 電話 | Y17: 電話 | Z17: 電話 | AA17: 電話 | BC17: 使用項目：ケース(Case) .客体申出情報 市区町村コード (MunicipalityCode__c)
A18: =ROW()-8 -> 10 | B18: 調査区番号 | K18: surveyId | L18: ContractStreetAddress__c | M18: ContractStreetAddress__c | N18: ContractStreetAddress__c | O18: ContractStreetAddress__c | P18: ContractStreetAddress__c | Q18: ContractStreetAddress__c | R18: ContractStreetAddress__c | S18: ContractStreetAddress__c | T18: I | V18: テキスト | W18: 電話 | X18: 電話 | Y18: 電話 | Z18: 電話 | AA18: 電話 | BC18: 使用項目：ケース(Case) .客体申出情報 調査区番号 (DistrictNumber__c)
A19: =ROW()-8 -> 11 | B19: 事業所番号 | K19: surveyId | L19: ContractStreetAddress__c | M19: ContractStreetAddress__c | N19: ContractStreetAddress__c | O19: ContractStreetAddress__c | P19: ContractStreetAddress__c | Q19: ContractStreetAddress__c | R19: ContractStreetAddress__c | S19: ContractStreetAddress__c | T19: I | V19: テキスト | W19: 電話 | X19: 電話 | Y19: 電話 | Z19: 電話 | AA19: 電話 | BC19: 使用項目：ケース(Case) .客体申出情報 事業所番号 (EstablishmentNumber__c)
A20: =ROW()-8 -> 12 | B20: ＊コード | K20: surveyId | L20: ContractStreetAddress__c | M20: ContractStreetAddress__c | N20: ContractStreetAddress__c | O20: ContractStreetAddress__c | P20: ContractStreetAddress__c | Q20: ContractStreetAddress__c | R20: ContractStreetAddress__c | S20: ContractStreetAddress__c | T20: I | V20: テキスト | W20: 電話 | X20: 電話 | Y20: 電話 | Z20: 電話 | AA20: 電話 | BC20: 使用項目：ケース(Case) .客体申出情報 ＊コード (MarkCode__c)
A21: =ROW()-8 -> 13 | B21: 整理番号 | K21: surveyId | L21: ContractStreetAddress__c | M21: ContractStreetAddress__c | N21: ContractStreetAddress__c | O21: ContractStreetAddress__c | P21: ContractStreetAddress__c | Q21: ContractStreetAddress__c | R21: ContractStreetAddress__c | S21: ContractStreetAddress__c | T21: I | V21: テキスト | W21: 電話 | X21: 電話 | Y21: 電話 | Z21: 電話 | AA21: 電話 | BC21: 使用項目：ケース(Case) .客体申出情報 整理番号 (RefNumber__c)
A22: =ROW()-8 -> 14 | B22: 書類のお届け先の住所と依頼者の住所が同じ | K22: isResendAddressSame | L22: ContractBuildingAndRoom__c | M22: ContractBuildingAndRoom__c | N22: ContractBuildingAndRoom__c | O22: ContractBuildingAndRoom__c | P22: ContractBuildingAndRoom__c | Q22: ContractBuildingAndRoom__c | R22: ContractBuildingAndRoom__c | S22: ContractBuildingAndRoom__c | T22: I | V22: チェックボックス | W22: テキスト | X22: テキスト | Y22: テキスト | Z22: テキスト | AA22: テキスト | BC22: 使用項目：ケース(Case) .調査書類の再送先が「WEB企業（個人事業主、もしくは団体）住所」と同じ (SameBusinessPersonDestination__c)
A23: =ROW()-8 -> 15 | B23: 書類お届け先企業名称 | K23: resendCompanyName | L23: InspectionRequestTimeTxt__c | M23: InspectionRequestTimeTxt__c | N23: InspectionRequestTimeTxt__c | O23: InspectionRequestTimeTxt__c | P23: InspectionRequestTimeTxt__c | Q23: InspectionRequestTimeTxt__c | R23: InspectionRequestTimeTxt__c | S23: InspectionRequestTimeTxt__c | T23: I | V23: テキスト | W23: 電話 | X23: 電話 | Y23: 電話 | Z23: 電話 | AA23: 電話 | BC23: 使用項目：ケース(Case) .書類お届け先企業名称 (DocumentResendCompanyName__c)
A24: =ROW()-8 -> 16 | B24: 書類のお届け先の郵便番号 | K24: resendPostcode | L24: InspectionRequestDate__c | M24: InspectionRequestDate__c | N24: InspectionRequestDate__c | O24: InspectionRequestDate__c | P24: InspectionRequestDate__c | Q24: InspectionRequestDate__c | R24: InspectionRequestDate__c | S24: InspectionRequestDate__c | T24: I | V24: テキスト | W24: 電話 | X24: 電話 | Y24: 電話 | Z24: 電話 | AA24: 電話 | BC24: 使用項目：ケース(Case) .書類再送先郵便番号 (DocumentResendPostCode__c)
A25: =ROW()-8 -> 17 | B25: 書類のお届け先の住所 | K25: resendAddress | L25: InspectionRequestTimeTxt__c | M25: InspectionRequestTimeTxt__c | N25: InspectionRequestTimeTxt__c | O25: InspectionRequestTimeTxt__c | P25: InspectionRequestTimeTxt__c | Q25: InspectionRequestTimeTxt__c | R25: InspectionRequestTimeTxt__c | S25: InspectionRequestTimeTxt__c | T25: I | V25: テキスト | W25: 電話 | X25: 電話 | Y25: 電話 | Z25: 電話 | AA25: 電話 | BC25: 使用項目：ケース(Case) .書類再送先住所 (DocumentResendAddress__c)
A26: =ROW()-8 -> 18 | B26: 調査書類希望理由 | K26: researchDocumentReasonHope | L26: InspectionAttendeeName__c | M26: InspectionAttendeeName__c | N26: InspectionAttendeeName__c | O26: InspectionAttendeeName__c | P26: InspectionAttendeeName__c | Q26: InspectionAttendeeName__c | R26: InspectionAttendeeName__c | S26: InspectionAttendeeName__c | T26: I | V26: テキスト | W26: 電話 | X26: 電話 | Y26: 電話 | Z26: 電話 | AA26: 電話 | BC26: 使用項目：ケース(Case) .調査書類希望理由 (PostCode__c)

Sheet 画面機能定義書
A1: システム名 | G1: =IF(ISBLANK(画面定義書Step1!G1),"",画面定義書Step1!G1) -> 令和8年度経済センサス活動調査 | S1: 画 面 機 能 定 義 書 | AT1: 文書番号 | AX1: =IF(ISBLANK(画面定義書Step1!BG1),"",画面定義書Step1!BG1)
A2: サブシステム名 | G2: =IF(ISBLANK(画面定義書Step1!G2),"",画面定義書Step1!G2) -> - | AT2: 更新日 | AX2: 46069 | BC2: 更新者 | BG2: 方
A4: 機能ID | E4: =IF(ISBLANK(画面定義書Step1!E4),"",画面定義書Step1!E4) | I4: 画面ID | O4: =IF(ISBLANK(画面定義書Step1!O4),"",画面定義書Step1!O4) | U4: 画面名 | AA4: =IF(ISBLANK(画面定義書Step1!AA4),"",画面定義書Step1!AA4) -> 調査書類発送受付フォーム画面_Step1 | AM4: =IF(ISBLANK(画面定義書Step1!AQ4),"",画面定義書Step1!AQ4) -> documentsResendFormInput | AX4: 分類 | BC4: =IF(ISBLANK(画面定義書Step1!BL4),"",画面定義書Step1!BL4) -> カスタム画面
A5: 項番 | B5: 画面機能ID | H5: 画面機能名 | AF5: 画面機能説明
H6: 論理名 | T6: 物理名
A7: 1 | B7: - | H7: 【調査書類発送受付フォーム】 事業所の名称 | T7: - | AF7: 利用者が「書類の発送先の住所は依頼者の住所と同じ」を選択した場合、依頼者の住所を発送先住所に自動反映する。
A8: 2 | B8: - | H8: 【調査書類発送受付フォーム】 事業所の郵便番号 | T8: - | AF8: 利用者が郵便番号を入力した場合、郵便番号から住所検索を行い、取得できた住所（都道府県・市区町村等）を住所欄に自動反映する。
A9: 3 | B9: - | H9: 【調査書類発送受付フォーム】 書類のお届け先の郵便番号 | T9: - | AF9: 利用者が郵便番号を入力した場合、郵便番号から住所検索を行い、取得できた住所（都道府県・市区町村等）を住所欄に自動反映する。

Sheet 関連チェック仕様書
A1: システム名 | G1: =IF(ISBLANK(画面定義書Step1!G1),"",画面定義書Step1!G1) -> 令和8年度経済センサス活動調査 | S1: 関 連 チ ェ ッ ク 仕 様 書 | AT1: 文書番号 | AX1: =IF(ISBLANK(画面定義書Step1!BG1),"",画面定義書Step1!BG1)
A2: サブシステム名 | G2: =IF(ISBLANK(画面定義書Step1!G2),"",画面定義書Step1!G2) -> - | AT2: 更新日 | AX2: 46079 | BC2: 更新者 | BG2: 方
A4: 機能ID | E4: =IF(ISBLANK(画面定義書Step1!E4),"",画面定義書Step1!E4) | I4: 画面ID | O4: =IF(ISBLANK(画面定義書Step1!O4),"",画面定義書Step1!O4) | U4: 画面名 | AA4: =IF(ISBLANK(画面定義書Step1!AA4),"",画面定義書Step1!AA4) -> 調査書類発送受付フォーム画面_Step1 | AM4: =IF(ISBLANK(画面定義書Step1!AQ4),"",画面定義書Step1!AQ4) -> documentsResendFormInput | AX4: 分類 | BC4: =IF(ISBLANK(画面定義書Step1!BL4),"",画面定義書Step1!BL4) -> カスタム画面
A5: 項番 | B5: チェックID | H5: チェック項目 | S5: 関連チェック内容 | BG5: エラー コード
B6: - | H6: 【調査書類発送受付フォーム】 必須項目のチェック | S6: ■チェックロジック 画面の全ての必須項目を入力せずに、「入力内容の確認」ボタンをクリックした場合、エラーメッセージを表示する。 ■エラーメッセージ： ｘｘｘを入力してください | BG6: -
B7: - | H7: 【調査書類発送受付フォーム】 メールアドレス | S7: ■チェックロジック 画面項目「メールアドレス」と「メールアドレスの確認」のフォーマットが正しくない場合、エラーメッセージを表示する。 正規表現を使用してメールアドレスの形式をチェックします： • ^ - 文字列の開始 • [A-Za-z0-9]{1} - 最初の文字は英数字のみ • [A-Za-z0-9_.\-+]* - その後は英数字、アンダースコア、ドット、ハイフン、プラス記号が可能 • @{1} - @マークが必須 • [A-Za-z0-9_.-]+ - @の後には英数字、アンダースコア、ドット、ハイフンが1文字以上必要 • \. - ドットが必須 • [A-Za-z0-9]+ - ドメイン部分は英数字が1文字以上必要 • $ - 文字列の終わり 例えば： valid@example.com （有効） user.name+tag@domain.com （有効） @invalid.com （@マークの前に文字がないため無効） invalid@ （ドットがないため無効） ■エラーメッセージ： 有効なメールアドレスを入力してください。 | BG7: -
B8: - | H8: 【調査書類発送受付フォーム】 電話番号 | S8: ■チェックロジック 画面項目「電話番号」のフォーマットが正しくない場合、エラーメッセージを表示する。 正規表現を使用して電話番号の形式をチェックします： • ^ - 文字列の開始 • [0-9+\-()] は文字クラスで、以下の文字を許可します： 数字 (0-9) プラス記号 (+) ハイフン (-) 括弧 ( ) • {1,20} は前の文字クラスが1回から20回まで出現可能であることを示します • $ は文字列の末尾を示します 例えば： "1234567890" （有効） "+1-234-567-8900" （有効） "(123)4567890" （有効） "abc123" (文字が含まれているため無効) "12345678901234567890123" (20文字を超えているため無効) ■エラーメッセージ： 申請者の電話番号を入力してください | BG8: -
B9: - | H9: 【調査書類発送受付フォーム】 事業所の郵便番号 | S9: ■チェックロジック 画面項目「事業所の郵便番号」のフォーマットが正しくない場合、エラーメッセージを表示する。 ハイフンなしの半角数字 ■エラーメッセージ： 書類を発送する郵便番号を正しいフォーマットで入力してください | BG9: -
B10: - | H10: 【調査書類発送受付フォーム】 市区町村コード | S10: ■チェックロジック 画面項目「市区町村コード」のフォーマットが正しくない場合、エラーメッセージを表示する。 正規表現を使用して市区町村コードの形式をチェックします： ・ ^ - 文字列の開始 ・ [0-9] は文字クラスで、数字(0-9)を許可します ・ {5} は前の文字クラスが5回出現することを示します ・ $ は文字列の末尾を示します 例えば： "12345" (有効) "1234" (桁数が足りないため無効) "123456" (桁数が多いため無効) "1234a" (文字が含まれているため無効) ■エラーメッセージ： ・未入力の場合： 市区町村コードを入力してください ・フォーマットが正しくない場合： 市区町村コードを5桁の半角数字で入力してください | BG10: -
B11: - | H11: 【調査書類発送受付フォーム】 調査区番号 | S11: ■チェックロジック 画面項目「調査区番号」のフォーマットが正しくない場合、エラーメッセージを表示する。 正規表現を使用して調査区番号の形式をチェックします： ・ ^ - 文字列の開始 ・ [0-9] は文字クラスで、数字(0-9)を許可します ・ {4} は前の文字クラスが4回出現することを示します ・ $ は文字列の末尾を示します 例えば： "1234" (有効) "123" (桁数が足りないため無効) "12345" (桁数が多いため無効) "123a" (文字が含まれているため無効) ■エラーメッセージ： ・未入力の場合： 調査区番号を入力してください ・フォーマットが正しくない場合： 調査区番号を4桁の半角数字で入力してください | BG11: -
B12: - | H12: 【調査書類発送受付フォーム】 事業所番号 | S12: ■チェックロジック 画面項目「事業所番号」のフォーマットが正しくない場合、エラーメッセージを表示する。 正規表現を使用して事業所番号の形式をチェックします： ・ ^ - 文字列の開始 ・ [0-9] は文字クラスで、数字(0-9)を許可します ・ {4} は前の文字クラスが4回出現することを示します ・ $ は文字列の末尾を示します 例えば： "1234" (有効) "123" (桁数が足りないため無効) "12345" (桁数が多いため無効) "123a" (文字が含まれているため無効) ■エラーメッセージ： ・未入力の場合： 事業所番号を入力してください ・フォーマットが正しくない場合： 事業所番号を4桁の半角数字で入力してください | BG12: -
B13: - | H13: 【調査書類発送受付フォーム】 ＊コード | S13: ■チェックロジック 画面項目「＊コード」のフォーマットが正しくない場合、エラーメッセージを表示する。 正規表現を使用して＊コードの形式をチェックします： ・ ^ - 文字列の開始 ・ [0-9] は文字クラスで、数字(0-9)を許可します ・ {1} は前の文字クラスが1回出現することを示します ・ $ は文字列の末尾を示します 例えば： "1" (有効) "12" (桁数が多いため無効) "a" (文字が含まれているため無効) ■エラーメッセージ： ・未入力の場合： ＊コードを入力してください ・フォーマットが正しくない場合： ＊コードを1桁の半角数字で入力してください | BG13: -
B14: - | H14: 【調査書類発送受付フォーム】 整理番号 | S14: ■チェックロジック 画面項目「整理番号」が入力されているかつ、フォーマットが正しくない場合、エラーメッセージを表示する。 正規表現を使用して整理番号の形式をチェックします： ・ ^ - 文字列の開始 ・ [0-9] は文字クラスで、数字(0-9)を許可します ・ {5} は前の文字クラスが5回出現することを示します ・ $ は文字列の末尾を示します 例えば： "12345" (有効) "" (未入力も有効) "1234" (桁数が足りないため無効) "123456" (桁数が多いため無効) "1234a" (文字が含まれているため無効) ■エラーメッセージ： ・フォーマットが正しくない場合： 整理番号を5桁の半角数字で入力してください | BG14: -
B15: - | H15: 【調査書類発送受付フォーム】 書類のお届け先の郵便番号 | S15: ■チェックロジック 画面項目書書類のお届け先の郵便番」のフォーマットが正しくない場合、エラーメッセージを表示する。 ハイフンなしの半角数字 ■エラーメッセージ： 書類を発送する郵便番号を正しいフォーマットで入力してください | BG15: -

Sheet 補足説明書
A1: システム名 | G1: FACTORS | S1: 補 足 説 明 書 | AT1: 文書番号 | AX1: ANA_DS207
A2: サブシステム名 | G2: - | AT2: 更新日 | AX2: 43038 | BC2: 更新者 | BG2: CITS
A4: 機能ID | E4: AFMWEB | I4: 画面ID | O4: AFMWEB004 | U4: 画面名 | AA4: 予約各種情報入力画面 | AM4: RentryPage | AX4: 分類 | BC4: 入力フォーム
A5: 補足説明
C7: 1．画面初期表示データ取得
D9: （１）予約枠空き状況確認・見学日選定画面で新規した予約の取得
E10: ① | F10: 対象オブジェクト
F11: 予約
E13: ② | F13: ソート条件
F14: なし
E16: ③ | F16: 検索条件
F17: 以下の条件で検索する
I18: 検索対象項目 | Y18: 検索方法
G19: 項番 | I19: 表示ラベル（項目） | P19: API参照名（項目）
G20: 1 | I20: Id | P20: Id | Y20: Id = :前画面で新規した予約のIｄ
E22: ④検索結果
G23: 画面項目 | O23: オブジェクト名 | V23: Reservat__c
G24: 項番 | I24: 項目名 | O24: 表示ラベル（項目） | AA24: API参照名（項目） | AM24: 備考
G25: 1 | I25: - | O25: 見学日 | AA25: ReservatDate__c
G26: 2 | I26: - | O26: ステータス | AA26: ReservaStatus__c
G27: 3 | I27: - | O27: 見学人数 | AA27: ReservaNumber__c
G28: 4 | I28: - | O28: 見学コース | AA28: ReservatCourse__c
G29: 5 | I29: - | O29: 代表者 | AA29: Representative__c
D33: （２）車いす可能追加台数の取得
E34: ① | F34: 対象オブジェクト
F35: 予約枠
E37: ② | F37: ソート条件
F38: なし
E41: ③ | F41: 検索条件
F42: 以下の条件で検索する
I43: 検索対象項目 | Y43: 検索方法
G44: 項番 | I44: 表示ラベル（項目） | P44: API参照名（項目）
G45: 1 | I45: 見学希望日 | P45: ReservatDate__c | Y45: ReservatDate__c = :見学日
E48: ④検索結果
G49: 画面項目 | O49: オブジェクト名 | V49: ReservatFrame__c
G50: 項番 | I50: 項目名 | O50: 表示ラベル（項目） | AA50: API参照名（項目） | AM50: 備考
G51: 1 | I51: - | O51: 予約日付 | AA51: ReservatDate__c
G52: 2 | I52: - | O52: 車いす残台数(第1回) | AA52: UnsoldWheelchairCount1__c
G53: 3 | I53: - | O53: 車いす残台数(第２回) | AA53: UnsoldWheelchairCount2__c
G54: 4 | I54: - | O54: 車いす残台数(第３回) | AA54: UnsoldWheelchairCount3__c
...
